 torchrun --standalone --nnodes=1  --nproc_per_node=2  train_direct_ddp.py --savedir './test_train_ddp1' --args 'train_args_min.json'
WARNING:torch.distributed.run:
*****************************************
Setting OMP_NUM_THREADS environment variable for each process to be 1 in default, to avoid your system being overloaded, please further tune the variable for optimal performance in your application as needed. 
*****************************************
Start running SchNet on rank 0.
Start running SchNet on rank 1.
[2652958]: world_size = 2, rank = 0, backend=nccl 
num_gpus: 2
Running the DDP model
[2652959]: world_size = 2, rank = 1, backend=nccl 
num_gpus: 2
Running the DDP model
libibverbs: Warning: couldn't load driver 'librxe-rdmav34.so': librxe-rdmav34.so: cannot open shared object file: No such file or directory
libibverbs: Warning: couldn't load driver 'libmlx4-rdmav34.so': libmlx4-rdmav34.so: cannot open shared object file: No such file or directory
libibverbs: Warning: couldn't load driver 'librxe-rdmav34.so': librxe-rdmav34.so: cannot open shared object file: No such file or directory
libibverbs: Warning: couldn't load driver 'libmlx4-rdmav34.so': libmlx4-rdmav34.so: cannot open shared object file: No such file or directory
Using device Using device   cudacuda

/mnt/beegfs/home/pearl061/.conda/envs/hydroFinal/lib/python3.8/site-packages/torch_geometric/deprecation.py:12: UserWarning: 'data.DataLoader' is deprecated, use 'loader.DataLoader' instead
  warnings.warn(out)
Train data size 3571791
train_loader size 3571791
val_loader size 446473
/mnt/beegfs/home/pearl061/.conda/envs/hydroFinal/lib/python3.8/site-packages/torch_geometric/deprecation.py:12: UserWarning: 'data.DataLoader' is deprecated, use 'loader.DataLoader' instead
  warnings.warn(out)
Train data size 3571791
train_loader size 3571791
val_loader size 446473
type(train_loader):  <class 'torch_geometric.loader.dataloader.DataLoader'>
type(train_loader):  <class 'torch_geometric.loader.dataloader.DataLoader'>
Training with dataset of size 13953 on rank 1
Training with dataset of size 13953 on rank 0
Traceback (most recent call last):
  File "train_direct_ddp.py", line 168, in <module>
    main(args)
  File "train_direct_ddp.py", line 131, in main
    train_loss = train_ddp.train_energy_only_ddp(args, device_id, 
  File "/mnt/beegfs/home/pearl061/swDev/hydronet_parallel/utils/train_ddp.py", line 44, in train_energy_only_ddp
Traceback (most recent call last):
  File "train_direct_ddp.py", line 168, in <module>
    for batch_id, data in enumerate(loader):    main(args)
  File "train_direct_ddp.py", line 131, in main

  File "/mnt/beegfs/home/pearl061/.conda/envs/hydroFinal/lib/python3.8/site-packages/torch/utils/data/dataloader.py", line 652, in __next__
    train_loss = train_ddp.train_energy_only_ddp(args, device_id, 
  File "/mnt/beegfs/home/pearl061/swDev/hydronet_parallel/utils/train_ddp.py", line 44, in train_energy_only_ddp
    for batch_id, data in enumerate(loader):
  File "/mnt/beegfs/home/pearl061/.conda/envs/hydroFinal/lib/python3.8/site-packages/torch/utils/data/dataloader.py", line 652, in __next__
        data = self._next_data()data = self._next_data()
  File "/mnt/beegfs/home/pearl061/.conda/envs/hydroFinal/lib/python3.8/site-packages/torch/utils/data/dataloader.py", line 692, in _next_data

  File "/mnt/beegfs/home/pearl061/.conda/envs/hydroFinal/lib/python3.8/site-packages/torch/utils/data/dataloader.py", line 692, in _next_data
    data = self._dataset_fetcher.fetch(index)  # may raise StopIteration
  File "/mnt/beegfs/home/pearl061/.conda/envs/hydroFinal/lib/python3.8/site-packages/torch/utils/data/_utils/fetch.py", line 52, in fetch
    data = self._dataset_fetcher.fetch(index)  # may raise StopIteration
  File "/mnt/beegfs/home/pearl061/.conda/envs/hydroFinal/lib/python3.8/site-packages/torch/utils/data/_utils/fetch.py", line 52, in fetch
    return self.collate_fn(data)
  File "/mnt/beegfs/home/pearl061/.conda/envs/hydroFinal/lib/python3.8/site-packages/torch_geometric/loader/dataloader.py", line 19, in __call__
    return self.collate_fn(data)
  File "/mnt/beegfs/home/pearl061/.conda/envs/hydroFinal/lib/python3.8/site-packages/torch_geometric/loader/dataloader.py", line 19, in __call__
    return Batch.from_data_list(batch, self.follow_batch,
  File "/mnt/beegfs/home/pearl061/.conda/envs/hydroFinal/lib/python3.8/site-packages/torch_geometric/data/batch.py", line 76, in from_data_list
    return Batch.from_data_list(batch, self.follow_batch,
  File "/mnt/beegfs/home/pearl061/.conda/envs/hydroFinal/lib/python3.8/site-packages/torch_geometric/data/batch.py", line 76, in from_data_list
    batch, slice_dict, inc_dict = collate(
  File "/mnt/beegfs/home/pearl061/.conda/envs/hydroFinal/lib/python3.8/site-packages/torch_geometric/data/collate.py", line 46, in collate
    batch, slice_dict, inc_dict = collate(
  File "/mnt/beegfs/home/pearl061/.conda/envs/hydroFinal/lib/python3.8/site-packages/torch_geometric/data/collate.py", line 46, in collate
    for store in data.stores:
  File "/mnt/beegfs/home/pearl061/.conda/envs/hydroFinal/lib/python3.8/site-packages/torch_geometric/data/data.py", line 486, in stores
    for store in data.stores:
  File "/mnt/beegfs/home/pearl061/.conda/envs/hydroFinal/lib/python3.8/site-packages/torch_geometric/data/data.py", line 486, in stores
        return [self._store]return [self._store]
  File "/mnt/beegfs/home/pearl061/.conda/envs/hydroFinal/lib/python3.8/site-packages/torch_geometric/data/data.py", line 423, in __getattr__

  File "/mnt/beegfs/home/pearl061/.conda/envs/hydroFinal/lib/python3.8/site-packages/torch_geometric/data/data.py", line 423, in __getattr__
    raise RuntimeError(    raise RuntimeError(
RuntimeError: The 'data' object was created by an older version of PyG. If this error occurred while loading an already existing dataset, remove the 'processed/' directory in the dataset's root folder and try again.

RuntimeError: The 'data' object was created by an older version of PyG. If this error occurred while loading an already existing dataset, remove the 'processed/' directory in the dataset's root folder and try again.
ERROR:torch.distributed.elastic.multiprocessing.api:failed (exitcode: 1) local_rank: 0 (pid: 2652958) of binary: /mnt/beegfs/home/pearl061/.conda/envs/hydroFinal/bin/python
Traceback (most recent call last):
  File "/mnt/beegfs/home/pearl061/.conda/envs/hydroFinal/bin/torchrun", line 33, in <module>
    sys.exit(load_entry_point('torch==1.12.0', 'console_scripts', 'torchrun')())
  File "/mnt/beegfs/home/pearl061/.conda/envs/hydroFinal/lib/python3.8/site-packages/torch/distributed/elastic/multiprocessing/errors/__init__.py", line 345, in wrapper
    return f(*args, **kwargs)
  File "/mnt/beegfs/home/pearl061/.conda/envs/hydroFinal/lib/python3.8/site-packages/torch/distributed/run.py", line 761, in main
    run(args)
  File "/mnt/beegfs/home/pearl061/.conda/envs/hydroFinal/lib/python3.8/site-packages/torch/distributed/run.py", line 752, in run
    elastic_launch(
  File "/mnt/beegfs/home/pearl061/.conda/envs/hydroFinal/lib/python3.8/site-packages/torch/distributed/launcher/api.py", line 131, in __call__
    return launch_agent(self._config, self._entrypoint, list(args))
  File "/mnt/beegfs/home/pearl061/.conda/envs/hydroFinal/lib/python3.8/site-packages/torch/distributed/launcher/api.py", line 245, in launch_agent
    raise ChildFailedError(
torch.distributed.elastic.multiprocessing.errors.ChildFailedError: 
============================================================
train_direct_ddp.py FAILED
------------------------------------------------------------
Failures:
[1]:
  time      : 2023-04-11_19:47:37
  host      : mn2.pearl.scd.stfc.ac.uk
  rank      : 1 (local_rank: 1)
  exitcode  : 1 (pid: 2652959)
  error_file: <N/A>
  traceback : To enable traceback see: https://pytorch.org/docs/stable/elastic/errors.html
------------------------------------------------------------
Root Cause (first observed failure):
[0]:
  time      : 2023-04-11_19:47:37
  host      : mn2.pearl.scd.stfc.ac.uk
  rank      : 0 (local_rank: 0)
  exitcode  : 1 (pid: 2652958)
  error_file: <N/A>
  traceback : To enable traceback see: https://pytorch.org/docs/stable/elastic/errors.html
============================================================
